Workbook

Sheet SETUP
B2: Spreadsheet Setup
C5: Categories | D5: Descriptions
C6: Income | D6: CVS Income
C7: Income | D7: Apt 2 Rent
C8: Income | D8: Apt 3 Rent
C9: Income | D9: Uber Driver
C10: Property Expenses | D10: Mortgage
C11: Property Expenses | D11: Owner Contribution to Mortgage
C12: Property Expenses | D12: Landlord Electricity
C13: Property Expenses | D13: Water/Sewer (Monthly)
C14: Property Expenses | D14: Maintenance (Lawn)
C15: Property Expenses | D15: Maintenance (Lawn)
C16: Property Expenses | D16: Maintenance (Snow Removal)
... C46: Credit Card Payments | D46: CITIZENS Clear Value
C47: Savings
C48: Investments

Sheet 202601
C2: Season | D2: Summer
C4: =SUMIFS(E17:E89, D17:D89, "<=14") -> 1986.06 | D4: Expenses: 1st to 15th
C5: =SUMIFS(E17:E89, D17:D89, ">=15") -> 2449.61 | D5: Expenses: 15th to 30th
C7: Description | D7: Expected Due Date | E7: Amount | G7: Date Input? | H7: Description | I7: Expected Due Date | J7: Amount | K7: Pull into CASHFLOW
B8: =IFERROR(NOT(ISBLANK(D8)), FALSE) -> TRUE | C8: CVS Income | D8: 15 | E8: 3205.07 | G8: =NOT(ISBLANK(D8)) -> TRUE | H8: =IFERROR(__xludf.DUMMYFUNCTION("FILTER($C$8:$E$96, $G8:$G$96)"),"CVS Income") -> CVS Income | I8: =IFERROR(__xludf.DUMMYFUNCTION("""COMPUTED_VALUE"""),15) -> 15 | J8: =IFERROR(__xludf.DUMMYFUNCTION("""COMPUTED_VALUE"""),3205.07) -> 3205.07 | K8: =NOT(ISBLANK(H8)) -> TRUE
B9: =IFERROR(NOT(ISBLANK(D9)), FALSE) -> TRUE | C9: CVS Income | D9: 30 | E9: 3205.07 | G9: =NOT(ISBLANK(D9)) -> TRUE | H9: =IFERROR(__xludf.DUMMYFUNCTION("""COMPUTED_VALUE"""),"CVS Income") -> CVS Income | I9: =IFERROR(__xludf.DUMMYFUNCTION("""COMPUTED_VALUE"""),30) -> 30 | J9: =IFERROR(__xludf.DUMMYFUNCTION("""COMPUTED_VALUE"""),3205.07) -> 3205.07 | K9: =NOT(ISBLANK(H9)) -> TRUE
B10: =IFERROR(NOT(ISBLANK(D10)), FALSE) -> FALSE | C10: Apt 2 Rent | G10: =NOT(ISBLANK(D10)) -> FALSE | H10: =IFERROR(__xludf.DUMMYFUNCTION("""COMPUTED_VALUE"""),"BOA Customized Rewards") -> BOA Customized Rewards | I10: =IFERROR(__xludf.DUMMYFUNCTION("""COMPUTED_VALUE"""),9) -> 9 | K10: =NOT(ISBLANK(H10)) -> TRUE
B11: =IFERROR(NOT(ISBLANK(D11)), FALSE) -> FALSE | C11: Apt 3 Rent | G11: =NOT(ISBLANK(D11)) -> FALSE | H11: =IFERROR(__xludf.DUMMYFUNCTION("""COMPUTED_VALUE"""),"BOA Unlimited Rewards") -> BOA Unlimited Rewards | I11: =IFERROR(__xludf.DUMMYFUNCTION("""COMPUTED_VALUE"""),4) -> 4 | J11: =IFERROR(__xludf.DUMMYFUNCTION("""COMPUTED_VALUE"""),151) -> 151 | K11: =NOT(ISBLANK(H11)) -> TRUE
B12: =IFERROR(NOT(ISBLANK(D12)), FALSE) -> FALSE | C12: Uber Income | G12: =NOT(ISBLANK(D12)) -> FALSE | H12: =IFERROR(__xludf.DUMMYFUNCTION("""COMPUTED_VALUE"""),"CHASE Freedom") -> CHASE Freedom | I12: =IFERROR(__xludf.DUMMYFUNCTION("""COMPUTED_VALUE"""),15) -> 15 | K12: =NOT(ISBLANK(H12)) -> TRUE
B13: =IFERROR(NOT(ISBLANK(D13)), FALSE) -> FALSE | G13: =NOT(ISBLANK(D13)) -> FALSE | H13: =IFERROR(__xludf.DUMMYFUNCTION("""COMPUTED_VALUE"""),"CITI Diamond Preferred") -> CITI Diamond Preferred | I13: =IFERROR(__xludf.DUMMYFUNCTION("""COMPUTED_VALUE"""),15) -> 15 | J13: =IFERROR(__xludf.DUMMYFUNCTION("""COMPUTED_VALUE"""),120) -> 120 | K13: =NOT(ISBLANK(H13)) -> TRUE
B14: =IFERROR(NOT(ISBLANK(D14)), FALSE) -> FALSE | C14: Total Income | E14: =SUM(E8:E12) -> 6410.14 | G14: =NOT(ISBLANK(D14)) -> FALSE | H14: =IFERROR(__xludf.DUMMYFUNCTION("""COMPUTED_VALUE"""),"CITIZENS Clear Value") -> CITIZENS Clear Value | I14: =IFERROR(__xludf.DUMMYFUNCTION("""COMPUTED_VALUE"""),13) -> 13 | J14: =IFERROR(__xludf.DUMMYFUNCTION("""COMPUTED_VALUE"""),64) -> 64 | K14: =NOT(ISBLANK(H14)) -> TRUE
B15: =IFERROR(NOT(ISBLANK(D15)), FALSE) -> FALSE | G15: =NOT(ISBLANK(D15)) -> FALSE | H15: =IFERROR(__xludf.DUMMYFUNCTION("""COMPUTED_VALUE"""),"CITIZENS HELOC") -> CITIZENS HELOC | I15: =IFERROR(__xludf.DUMMYFUNCTION("""COMPUTED_VALUE"""),15) -> 15 | J15: =IFERROR(__xludf.DUMMYFUNCTION("""COMPUTED_VALUE"""),95.95) -> 95.95 | K15: =NOT(ISBLANK(H15)) -> TRUE
B16: =IFERROR(NOT(ISBLANK(D16)), FALSE) -> FALSE | C16: Credit Cards | G16: =NOT(ISBLANK(D16)) -> FALSE | H16: =IFERROR(__xludf.DUMMYFUNCTION("""COMPUTED_VALUE"""),"UPSTART Debt Consolidation") -> UPSTART Debt Consolidation | I16: =IFERROR(__xludf.DUMMYFUNCTION("""COMPUTED_VALUE"""),15) -> 15 | J16: =IFERROR(__xludf.DUMMYFUNCTION("""COMPUTED_VALUE"""),181.13) -> 181.13 | K16: =NOT(ISBLANK(H16)) -> TRUE
B17: =IFERROR(NOT(ISBLANK(D17)), FALSE) -> TRUE | C17: BOA Customized Rewards | D17: 9 | G17: =NOT(ISBLANK(D17)) -> TRUE | H17: =IFERROR(__xludf.DUMMYFUNCTION("""COMPUTED_VALUE"""),"AQUA FINANCE Roofing Replacement") -> AQUA FINANCE Roofing Replacement | I17: =IFERROR(__xludf.DUMMYFUNCTION("""COMPUTED_VALUE"""),6) -> 6 | J17: =IFERROR(__xludf.DUMMYFUNCTION("""COMPUTED_VALUE"""),268.44) -> 268.44 | K17: =NOT(ISBLANK(H17)) -> TRUE
C18: BOA Unlimited Rewards | D18: 4 | E18: 151 | G18: =NOT(ISBLANK(D18)) -> TRUE | H18: =IFERROR(__xludf.DUMMYFUNCTION("""COMPUTED_VALUE"""),"TD Auto Loan") -> TD Auto Loan | I18: =IFERROR(__xludf.DUMMYFUNCTION("""COMPUTED_VALUE"""),17) -> 17 | J18: =IFERROR(__xludf.DUMMYFUNCTION("""COMPUTED_VALUE"""),595) -> 595 | K18: =NOT(ISBLANK(H18)) -> TRUE
C19: CHASE Freedom | D19: 15 | G19: =NOT(ISBLANK(D19)) -> TRUE | H19: =IFERROR(__xludf.DUMMYFUNCTION("""COMPUTED_VALUE"""),"Owner Contribution to Mortgage") -> Owner Contribution to Mortgage | I19: =IFERROR(__xludf.DUMMYFUNCTION("""COMPUTED_VALUE"""),1) -> 1 | J19: =IFERROR(__xludf.DUMMYFUNCTION("""COMPUTED_VALUE"""),146.54) -> 146.54 | K19: =NOT(ISBLANK(H19)) -> TRUE
C20: CITI Diamond Preferred | D20: 15 | E20: 120 | G20: =NOT(ISBLANK(D20)) -> TRUE | H20: =IFERROR(__xludf.DUMMYFUNCTION("""COMPUTED_VALUE"""),"Landlord Electricity") -> Landlord Electricity | I20: =IFERROR(__xludf.DUMMYFUNCTION("""COMPUTED_VALUE"""),1) -> 1 | J20: =IFERROR(__xludf.DUMMYFUNCTION("""COMPUTED_VALUE"""),33.16) -> 33.16 | K20: =NOT(ISBLANK(H20)) -> TRUE
B21: =IFERROR(NOT(ISBLANK(D21)), FALSE) -> TRUE | C21: CITIZENS Clear Value | D21: 13 | E21: 64 | G21: =NOT(ISBLANK(D21)) -> TRUE | H21: =IFERROR(__xludf.DUMMYFUNCTION("""COMPUTED_VALUE"""),"Maintenance (Lawn)") -> Maintenance (Lawn) | I21: =IFERROR(__xludf.DUMMYFUNCTION("""COMPUTED_VALUE"""),10) -> 10 | J21: =IFERROR(__xludf.DUMMYFUNCTION("""COMPUTED_VALUE"""),80) -> 80 | K21: =NOT(ISBLANK(H21)) -> TRUE
B22: =IFERROR(NOT(ISBLANK(D22)), FALSE) -> FALSE | G22: =NOT(ISBLANK(D22)) -> FALSE | H22: =IFERROR(__xludf.DUMMYFUNCTION("""COMPUTED_VALUE"""),"Maintenance (Lawn)") -> Maintenance (Lawn) | I22: =IFERROR(__xludf.DUMMYFUNCTION("""COMPUTED_VALUE"""),24) -> 24 | J22: =IFERROR(__xludf.DUMMYFUNCTION("""COMPUTED_VALUE"""),80) -> 80 | K22: =NOT(ISBLANK(H22)) -> TRUE
B23: =IFERROR(NOT(ISBLANK(D23)), FALSE) -> FALSE | C23: Loan Payments | G23: =NOT(ISBLANK(D23)) -> FALSE | H23: =IFERROR(__xludf.DUMMYFUNCTION("""COMPUTED_VALUE"""),"Blink Security") -> Blink Security | I23: =IFERROR(__xludf.DUMMYFUNCTION("""COMPUTED_VALUE"""),1) -> 1 | J23: =IFERROR(__xludf.DUMMYFUNCTION("""COMPUTED_VALUE"""),10.64) -> 10.64 | K23: =NOT(ISBLANK(H23)) -> TRUE
B24: =IFERROR(NOT(ISBLANK(D24)), FALSE) -> TRUE | C24: CITIZENS HELOC | D24: 15 | E24: 380 | G24: =NOT(ISBLANK(D24)) -> TRUE | H24: =IFERROR(__xludf.DUMMYFUNCTION("""COMPUTED_VALUE"""),"Avail Portal") -> Avail Portal | I24: =IFERROR(__xludf.DUMMYFUNCTION("""COMPUTED_VALUE"""),1) -> 1 | J24: =IFERROR(__xludf.DUMMYFUNCTION("""COMPUTED_VALUE"""),18) -> 18 | K24: =NOT(ISBLANK(H24)) -> TRUE
C25: UPSTART Debt Consolidation | D25: 15 | E25: 181.13 | G25: =NOT(ISBLANK(D25)) -> TRUE | H25: =IFERROR(__xludf.DUMMYFUNCTION("""COMPUTED_VALUE"""),"Auto Insurance") -> Auto Insurance | I25: =IFERROR(__xludf.DUMMYFUNCTION("""COMPUTED_VALUE"""),4) -> 4 | J25: =IFERROR(__xludf.DUMMYFUNCTION("""COMPUTED_VALUE"""),353.71) -> 353.71 | K25: =NOT(ISBLANK(H25)) -> TRUE
C26: AQUA FINANCE Roofing Replacement | D26: 6 | E26: 268.44 | G26: =NOT(ISBLANK(D26)) -> TRUE | H26: =IFERROR(__xludf.DUMMYFUNCTION("""COMPUTED_VALUE"""),"Heating/Natural Gas") -> Heating/Natural Gas | I26: =IFERROR(__xludf.DUMMYFUNCTION("""COMPUTED_VALUE"""),15) -> 15 | J26: =IFERROR(__xludf.DUMMYFUNCTION("""COMPUTED_VALUE"""),175) -> 175 | K26: =NOT(ISBLANK(H26)) -> TRUE
B27: =IFERROR(NOT(ISBLANK(D27)), FALSE) -> TRUE | C27: TD Auto Loan | D27: 17 | E27: 595 | G27: =NOT(ISBLANK(D27)) -> TRUE | H27: =IFERROR(__xludf.DUMMYFUNCTION("""COMPUTED_VALUE"""),"Electricity") -> Electricity | I27: =IFERROR(__xludf.DUMMYFUNCTION("""COMPUTED_VALUE"""),1) -> 1 | J27: =IFERROR(__xludf.DUMMYFUNCTION("""COMPUTED_VALUE"""),192.43) -> 192.43 | K27: =NOT(ISBLANK(H27)) -> TRUE
B28: =IFERROR(NOT(ISBLANK(D28)), FALSE) -> FALSE | C28: NELNET Student Loans | G28: =NOT(ISBLANK(D28)) -> FALSE | H28: =IFERROR(__xludf.DUMMYFUNCTION("""COMPUTED_VALUE"""),"Internet") -> Internet | I28: =IFERROR(__xludf.DUMMYFUNCTION("""COMPUTED_VALUE"""),27) -> 27 | J28: =IFERROR(__xludf.DUMMYFUNCTION("""COMPUTED_VALUE"""),74.95) -> 74.95 | K28: =NOT(ISBLANK(H28)) -> TRUE
B29: =IFERROR(NOT(ISBLANK(D29)), FALSE) -> FALSE | G29: =NOT(ISBLANK(D29)) -> FALSE | H29: =IFERROR(__xludf.DUMMYFUNCTION("""COMPUTED_VALUE"""),"Life Insurance") -> Life Insurance | I29: =IFERROR(__xludf.DUMMYFUNCTION("""COMPUTED_VALUE"""),16) -> 16 | J29: =IFERROR(__xludf.DUMMYFUNCTION("""COMPUTED_VALUE"""),82.37) -> 82.37 | K29: =NOT(ISBLANK(H29)) -> TRUE
B30: =IFERROR(NOT(ISBLANK(D30)), FALSE) -> FALSE | C30: Propery Expenses | G30: =NOT(ISBLANK(D30)) -> FALSE | H30: =IFERROR(__xludf.DUMMYFUNCTION("""COMPUTED_VALUE"""),"Groceries + Toiletries") -> Groceries + Toiletries | I30: =IFERROR(__xludf.DUMMYFUNCTION("""COMPUTED_VALUE"""),3) -> 3 | J30: =IFERROR(__xludf.DUMMYFUNCTION("""COMPUTED_VALUE"""),250) -> 250 | K30: =NOT(ISBLANK(H30)) -> TRUE
B31: =IFERROR(NOT(ISBLANK(D31)), FALSE) -> TRUE | C31: Owner Contribution to Mortgage | D31: 1 | E31: 146.54 | G31: =NOT(ISBLANK(D31)) -> TRUE | H31: =IFERROR(__xludf.DUMMYFUNCTION("""COMPUTED_VALUE"""),"Groceries + Toiletries") -> Groceries + Toiletries | I31: =IFERROR(__xludf.DUMMYFUNCTION("""COMPUTED_VALUE"""),10) -> 10 | J31: =IFERROR(__xludf.DUMMYFUNCTION("""COMPUTED_VALUE"""),250) -> 250 | K31: =NOT(ISBLANK(H31)) -> TRUE
B32: =IFERROR(NOT(ISBLANK(D32)), FALSE) -> TRUE | C32: Landlord Electricity | D32: 1 | E32: 33.16 | G32: =NOT(ISBLANK(D32)) -> TRUE | H32: =IFERROR(__xludf.DUMMYFUNCTION("""COMPUTED_VALUE"""),"Groceries + Toiletries") -> Groceries + Toiletries | I32: =IFERROR(__xludf.DUMMYFUNCTION("""COMPUTED_VALUE"""),17) -> 17 | J32: =IFERROR(__xludf.DUMMYFUNCTION("""COMPUTED_VALUE"""),250) -> 250 | K32: =NOT(ISBLANK(H32)) -> TRUE
B33: =IFERROR(NOT(ISBLANK(D33)), FALSE) -> FALSE | C33: Water/Sewer (Monthly) | E33: 130 | G33: =NOT(ISBLANK(D33)) -> FALSE | H33: =IFERROR(__xludf.DUMMYFUNCTION("""COMPUTED_VALUE"""),"Groceries + Toiletries") -> Groceries + Toiletries | I33: =IFERROR(__xludf.DUMMYFUNCTION("""COMPUTED_VALUE"""),24) -> 24 | J33: =IFERROR(__xludf.DUMMYFUNCTION("""COMPUTED_VALUE"""),250) -> 250 | K33: =NOT(ISBLANK(H33)) -> TRUE
B34: =IFERROR(NOT(ISBLANK(D34)), FALSE) -> TRUE | C34: Maintenance (Lawn) | D34: 10 | E34: =IF($D$2="Summer", 80, 0) -> 80 | G34: =NOT(ISBLANK(D34)) -> TRUE | H34: =IFERROR(__xludf.DUMMYFUNCTION("""COMPUTED_VALUE"""),"Phone (Nykosi)") -> Phone (Nykosi) | I34: =IFERROR(__xludf.DUMMYFUNCTION("""COMPUTED_VALUE"""),16) -> 16 | J34: =IFERROR(__xludf.DUMMYFUNCTION("""COMPUTED_VALUE"""),30) -> 30 | K34: =NOT(ISBLANK(H34)) -> TRUE
B35: =IFERROR(NOT(ISBLANK(D35)), FALSE) -> TRUE | C35: Maintenance (Lawn) | D35: 24 | E35: =IF($D$2="Summer", 80, 0) -> 80 | G35: =NOT(ISBLANK(D35)) -> TRUE | H35: =IFERROR(__xludf.DUMMYFUNCTION("""COMPUTED_VALUE"""),"Phone (Brittany)") -> Phone (Brittany) | I35: =IFERROR(__xludf.DUMMYFUNCTION("""COMPUTED_VALUE"""),16) -> 16 | J35: =IFERROR(__xludf.DUMMYFUNCTION("""COMPUTED_VALUE"""),50) -> 50 | K35: =NOT(ISBLANK(H35)) -> TRUE
B36: =IFERROR(NOT(ISBLANK(D36)), FALSE) -> FALSE | C36: Maintenance (Snow Removal) | E36: =IF($D$2="Winter", 110, 0) -> 0 | G36: =NOT(ISBLANK(D36)) -> FALSE | H36: =IFERROR(__xludf.DUMMYFUNCTION("""COMPUTED_VALUE"""),"Gym Membership (Nykosi)") -> Gym Membership (Nykosi) | I36: =IFERROR(__xludf.DUMMYFUNCTION("""COMPUTED_VALUE"""),24) -> 24 | J36: =IFERROR(__xludf.DUMMYFUNCTION("""COMPUTED_VALUE"""),22.23) -> 22.23 | K36: =NOT(ISBLANK(H36)) -> TRUE
B37: =IFERROR(NOT(ISBLANK(D37)), FALSE) -> TRUE | C37: Blink Security | D37: 1 | E37: 10.64 | G37: =NOT(ISBLANK(D37)) -> TRUE | H37: =IFERROR(__xludf.DUMMYFUNCTION("""COMPUTED_VALUE"""),"Gym Membership (Brittany)") -> Gym Membership (Brittany) | I37: =IFERROR(__xludf.DUMMYFUNCTION("""COMPUTED_VALUE"""),6) -> 6 | J37: =IFERROR(__xludf.DUMMYFUNCTION("""COMPUTED_VALUE"""),32.87) -> 32.87 | K37: =NOT(ISBLANK(H37)) -> TRUE
B38: =IFERROR(NOT(ISBLANK(D38)), FALSE) -> TRUE | C38: Avail Portal | D38: 1 | E38: 18 | G38: =NOT(ISBLANK(D38)) -> TRUE | H38: =IFERROR(__xludf.DUMMYFUNCTION("""COMPUTED_VALUE"""),"Gym Trainer (Brittany)") -> Gym Trainer (Brittany) | I38: =IFERROR(__xludf.DUMMYFUNCTION("""COMPUTED_VALUE"""),14) -> 14 | J38: =IFERROR(__xludf.DUMMYFUNCTION("""COMPUTED_VALUE"""),105.29) -> 105.29 | K38: =NOT(ISBLANK(H38)) -> TRUE
B39: =IFERROR(NOT(ISBLANK(D39)), FALSE) -> FALSE | G39: =NOT(ISBLANK(D39)) -> FALSE | H39: =IFERROR(__xludf.DUMMYFUNCTION("""COMPUTED_VALUE"""),"Gym Trainer (Brittany)") -> Gym Trainer (Brittany) | I39: =IFERROR(__xludf.DUMMYFUNCTION("""COMPUTED_VALUE"""),28) -> 28 | J39: =IFERROR(__xludf.DUMMYFUNCTION("""COMPUTED_VALUE"""),105.29) -> 105.29 | K39: =NOT(ISBLANK(H39)) -> TRUE
B40: =IFERROR(NOT(ISBLANK(D40)), FALSE) -> FALSE | C40: Bills | G40: =NOT(ISBLANK(D40)) -> FALSE | H40: =IFERROR(__xludf.DUMMYFUNCTION("""COMPUTED_VALUE"""),"Amazon Prime") -> Amazon Prime | I40: =IFERROR(__xludf.DUMMYFUNCTION("""COMPUTED_VALUE"""),14) -> 14 | J40: =IFERROR(__xludf.DUMMYFUNCTION("""COMPUTED_VALUE"""),14.99) -> 14.99 | K40: =NOT(ISBLANK(H40)) -> TRUE
B41: =IFERROR(NOT(ISBLANK(D41)), FALSE) -> TRUE | C41: Auto Insurance | D41: 4 | E41: 353.71 | G41: =NOT(ISBLANK(D41)) -> TRUE | H41: =IFERROR(__xludf.DUMMYFUNCTION("""COMPUTED_VALUE"""),"Microsoft 365") -> Microsoft 365 | I41: =IFERROR(__xludf.DUMMYFUNCTION("""COMPUTED_VALUE"""),17) -> 17 | J41: =IFERROR(__xludf.DUMMYFUNCTION("""COMPUTED_VALUE"""),14.14) -> 14.14 | K41: =NOT(ISBLANK(H41)) -> TRUE
B42: =IFERROR(NOT(ISBLANK(D42)), FALSE) -> FALSE | C42: Auto Taxes (Monthly) | G42: =NOT(ISBLANK(D42)) -> FALSE | H42: =IFERROR(__xludf.DUMMYFUNCTION("""COMPUTED_VALUE"""),"Netflix") -> Netflix | I42: =IFERROR(__xludf.DUMMYFUNCTION("""COMPUTED_VALUE"""),23) -> 23 | J42: =IFERROR(__xludf.DUMMYFUNCTION("""COMPUTED_VALUE"""),19.3) -> 19.3 | K42: =NOT(ISBLANK(H42)) -> TRUE
B43: =IFERROR(NOT(ISBLANK(D43)), FALSE) -> TRUE | C43: Heating/Natural Gas | D43: 15 | E43: 175 | G43: =NOT(ISBLANK(D43)) -> TRUE | H43: =IFERROR(__xludf.DUMMYFUNCTION("""COMPUTED_VALUE"""),"YNAB ") -> YNAB | I43: =IFERROR(__xludf.DUMMYFUNCTION("""COMPUTED_VALUE"""),9) -> 9 | J43: =IFERROR(__xludf.DUMMYFUNCTION("""COMPUTED_VALUE"""),14.99) -> 14.99 | K43: =NOT(ISBLANK(H43)) -> TRUE
...

Sheet DONOTUSE
A1: Category & Description Dropdowns
A2: Categories | B2: {=TRANSPOSE(_xlfn.UNIQUE(_xlfn._xlws.FILTER(SETUP!$C$6:$C$100, NOT(ISBLANK(SETUP!$C$6:$C$100))),FALSE,FALSE))} -> Income | C2: Property Expenses | D2: Fixed Expenses | E2: Variable Expenses | F2: Loan Payments | G2: Credit Card Payments | H2: Savings | I2: Investments
A3: {=_xlfn.UNIQUE(_xlfn._xlws.FILTER(SETUP!$C$6:$C$100, NOT(ISBLANK(SETUP!$C$6:$C$100))),FALSE,FALSE)} -> Income | B3: {=_xlfn._xlws.FILTER(SETUP!$D$6:$D$100, --(SETUP!$C$6:$C$100=B$2))} -> CVS Income | C3: {=_xlfn._xlws.FILTER(SETUP!$D$6:$D$100, --(SETUP!$C$6:$C$100=C$2))} -> Mortgage | D3: {=_xlfn._xlws.FILTER(SETUP!$D$6:$D$100, --(SETUP!$C$6:$C$100=D$2))} -> Auto Insurance | E3: {=_xlfn._xlws.FILTER(SETUP!$D$6:$D$100, --(SETUP!$C$6:$C$100=E$2))} -> Heating/Natural Gas | F3: {=_xlfn._xlws.FILTER(SETUP!$D$6:$D$100, --(SETUP!$C$6:$C$100=F$2))} -> CITIZENS HELOC | G3: {=_xlfn._xlws.FILTER(SETUP!$D$6:$D$100, --(SETUP!$C$6:$C$100=G$2))} -> BOA Customized Rewards | H3: {=_xlfn._xlws.FILTER(SETUP!$D$6:$D$100, --(SETUP!$C$6:$C$100=H$2))} -> 0 | I3: {=_xlfn._xlws.FILTER(SETUP!$D$6:$D$100, --(SETUP!$C$6:$C$100=I$2))} -> 0
A4: Property Expenses | B4: Apt 2 Rent | C4: Owner Contribution to Mortgage | D4: Auto Taxes (Monthly) | E4: Electricity | F4: UPSTART Debt Consolidation | G4: BOA Unlimited Rewards
A5: Fixed Expenses | B5: Apt 3 Rent | C5: Landlord Electricity | D5: Internet | E5: Groceries + Toiletries | F5: AQUA FINANCE Roofing Replacement | G5: CHASE Freedom
A6: Variable Expenses | B6: Uber Driver | C6: Water/Sewer (Monthly) | D6: Life Insurance | E6: Gym Trainer (Brittany) | F6: TD Auto Loan | G6: CITI Diamond Preferred
A7: Loan Payments | C7: Maintenance (Lawn) | D7: Phone (Nykosi) | F7: NELNET Student Loans | G7: CITIZENS Clear Value
A8: Credit Card Payments | C8: Maintenance (Lawn) | D8: Phone (Brittany) | F8: XXX Heating Systems
A9: Savings | C9: Maintenance (Snow Removal) | D9: Gym Membership (Nykosi)
A10: Investments | C10: Blink Security | D10: Gym Membership (Brittany)
C11: Avail Portal | D11: Amazon Prime
D12: Microsoft 365
D13: Netflix
D14: YNAB
D15: OpenAI

Sheet Budget
B2: Budget
B3: Category | C3: Description | D3: Due Date | E3: ="Amount "&" ("&'[1]Start Here'!$H$17&")" -> Amount ($) | F3: Include? | G3: Hide | H3: ="Amount for Cashflow "&" ("&'[1]Start Here'!$H$17&")" -> Amount for Cashflow ($)
B5: Loan Payments | C5: CITIZENS HELOC

Sheet Transactions
B2: Transactions
B3: Date | C3: Merchant | D3: Category | E3: Description | F3: ="Amount "&" ("&'[1]Start Here'!$H$17&")" -> Amount ($)

Sheet Budget_TEMPLATE
B2: ="Budget" -> Budget | G2: BUDGET VS ACTUAL CASHFLOW | L2: BUDGET STATUS | Q2: BUDGET SUMMARY | V2: BUDGET VS ACTUAL ALL CATEGORIES | AA2: WHERE DOES MY MONEY GO?
L3: LEFT TO BUDGET Total Budget Income less Total Budget Allocated | N3: ='[1]Start Here'!$H$17&TEXT(C130-SUM(M130,R130,W130,AB130,AG130),"#,##0") -> $0 | R3: Budget | S3: Actual | T3: Variance | AA3: BUDGET | AF3: ACTUAL
Q4: INCOME | R4: =B17 -> $0 | S4: =B20 -> $0 | T4: =IF(E130>=0,'[1]Start Here'!$H$25&TEXT(E130,"#,##0"),'[1]Start Here'!$H$25&TEXT(E130*-1,"#,##0")) -> 0
B6: BUDGET PERIOD | Q6: OUTGOINGS All Categories ex Income | R6: ='[1]Start Here'!$H$17&TEXT(SUM(M130,R130,W130,AB130,AG130),"#,##0") -> $0 | S6: ='[1]Start Here'!$H$17&TEXT(SUM(N130,S130,X130,AC130,AH130),"#,##0") -> $0 | T6: ='[1]Start Here'!$H$17&TEXT(SUM(N130,S130,X130,AC130,AH130)-SUM(M130,R130,W130,AB130,AG130),"#,##0") -> $0
B7: Start Date -> | C7: 45717
B8: End Date -> | C8: 45747 | L8: LEFT TO SPEND, SAVE, INVEST Total Actual Income less Total Actual Outgoings | N8: ='[1]Start Here'!$H$17&TEXT(D130-SUM(N130,S130,X130,AC130,AH130),"#,##0") -> $0 | Q8: NET Income less Outgoings | R8: ='[1]Start Here'!$H$17&TEXT(C130-SUM(M130,R130,W130,AB130,AG130),"#,##0") -> $0 | S8: ='[1]Start Here'!$H$17&TEXT(D130-SUM(N130,S130,X130,AC130,AH130),"#,##0") -> $0 | T8: ='[1]Start Here'!$H$17&TEXT((D130-SUM(N130,S130,X130,AC130,AH130))-(C130-SUM(M130,R130,W130,AB130,AG130)),"#,##0") -> $0
B9: ="Selected budget period is "&_xlfn.DAYS(C8,C7)&" days long" -> Selected budget period is 30 days long
Q11: % INCOME SAVED Total Savings / Total Income | R11: =AB130/C130 -> #DIV/0! | S11: =AC130/D130 -> #DIV/0! | T11: =S11-R11 -> #DIV/0!
B12: =TEXT(AU1072/AU1073,"#%")&" complete ("&IF(AU1071=1,AU1071&" day remaining)",AU1071&" days remaining)") -> #DIV/0! | G12: Starting Balance:
B15: INCOME | G15: PROPERY EXPENSES | L15: FIXED EXPENSES | Q15: VARIABLE EXPENSES | V15: LOAN REPAYMENTS | AA15: SAVINGS | AF15: INVESTMENTS
B17: ='[1]Start Here'!$H$17&TEXT(C130,"#,##0") -> $0 | G17: ='[1]Start Here'!$H$17&TEXT(H130,"#,##0") -> $0 | L17: ='[1]Start Here'!$H$17&TEXT(M130,"#,##0") -> $0 | Q17: ='[1]Start Here'!$H$17&TEXT(R130,"#,##0") -> $0 | V17: ='[1]Start Here'!$H$17&TEXT(W130,"#,##0") -> $0 | AA17: ='[1]Start Here'!$H$17&TEXT(AB130,"#,##0") -> $0 | AF17: ='[1]Start Here'!$H$17&TEXT(AG130,"#,##0") -> $0
C18: =IFERROR(D130/C130,"") | H18: =IFERROR(I130/H130,"") | M18: =IFERROR(N130/M130,"") | R18: =IFERROR(S130/R130,"") | W18: =IFERROR(X130/W130,"") | AB18: =IFERROR(AC130/AB130,"") | AG18: =IFERROR(AH130/AG130,"")
B19: TOTAL BUDGET | G19: TOTAL BUDGET | L19: TOTAL BUDGET | Q19: TOTAL BUDGET | V19: TOTAL BUDGET | AA19: TOTAL BUDGET | AF19: TOTAL BUDGET
B20: ='[1]Start Here'!$H$17&TEXT(D130,"#,##0") -> $0 | G20: ='[1]Start Here'!$H$17&TEXT(I130,"#,##0") -> $0 | L20: ='[1]Start Here'!$H$17&TEXT(N130,"#,##0") -> $0 | Q20: ='[1]Start Here'!$H$17&TEXT(S130,"#,##0") -> $0 | V20: ='[1]Start Here'!$H$17&TEXT(X130,"#,##0") -> $0 | AA20: ='[1]Start Here'!$H$17&TEXT(AC130,"#,##0") -> $0 | AF20: ='[1]Start Here'!$H$17&TEXT(AH130,"#,##0") -> $0
B22: TOTAL ACTUAL | G22: TOTAL ACTUAL | L22: TOTAL ACTUAL | Q22: TOTAL ACTUAL | V22: TOTAL ACTUAL | AA22: TOTAL ACTUAL | AF22: TOTAL ACTUAL
B23: =IF(D130-C130<0,'[1]Start Here'!$H$17&TEXT((D130-C130)*-1,"#,##0"),'[1]Start Here'!$H$17&TEXT((D130-C130),"#,##0")) -> $0 | G23: =IF(I130-H130<0,'[1]Start Here'!$H$17&TEXT((I130-H130)*-1,"#,##0"),'[1]Start Here'!$H$17&TEXT((I130-H130),"#,##0")) -> $0 | L23: =IF(N130-M130<0,'[1]Start Here'!$H$17&TEXT((N130-M130)*-1,"#,##0"),'[1]Start Here'!$H$17&TEXT((N130-M130),"#,##0")) -> $0 | Q23: =IF(S130-R130<0,'[1]Start Here'!$H$17&TEXT((S130-R130)*-1,"#,##0"),'[1]Start Here'!$H$17&TEXT((S130-R130),"#,##0")) -> $0 | V23: =IF(X130-W130<0,'[1]Start Here'!$H$17&TEXT((X130-W130)*-1,"#,##0"),'[1]Start Here'!$H$17&TEXT((X130-W130),"#,##0")) -> $0 | AA23: =IF(AC130-AB130<0,'[1]Start Here'!$H$17&TEXT((AC130-AB130)*-1,"#,##0"),'[1]Start Here'!$H$17&TEXT((AC130-AB130),"#,##0")) -> $0 | AF23: =IF(AH130-AG130<0,'[1]Start Here'!$H$17&TEXT((AH130-AG130)*-1,"#,##0"),'[1]Start Here'!$H$17&TEXT((AH130-AG130),"#,##0")) -> $0
B25: {=_xlfn.IFS( D130-C130<0,"UNDER BUDGET", D130-C130>0,"OVER BUDGET", D130-C130=0,"ON BUDGET ✅")} -> ON BUDGET ✅ | C25: ACTUAL VS BUDGET | G25: {=_xlfn.IFS( I130-H130<0,"UNDER BUDGET", I130-H130>0,"OVER BUDGET", I130-H130=0,"ON BUDGET ✅")} -> ON BUDGET ✅ | H25: ACTUAL VS BUDGET | L25: {=_xlfn.IFS( N130-M130<0,"UNDER BUDGET", N130-M130>0,"OVER BUDGET", N130-M130=0,"ON BUDGET ✅")} -> ON BUDGET ✅ | M25: ACTUAL VS BUDGET | Q25: {=_xlfn.IFS( S130-R130<0,"UNDER BUDGET", S130-R130>0,"OVER BUDGET", S130-R130=0,"ON BUDGET ✅")} -> ON BUDGET ✅ | R25: ACTUAL VS BUDGET | V25: {=_xlfn.IFS( X130-W130<0,"UNDER BUDGET", X130-W130>0,"OVER BUDGET", X130-W130=0,"ON BUDGET ✅")} -> ON BUDGET ✅ | W25: ACTUAL VS BUDGET | AA25: {=_xlfn.IFS( AC130-AB130<0,"UNDER BUDGET", AC130-AB130>0,"OVER BUDGET", AC130-AB130=0,"ON BUDGET ✅")} -> ON BUDGET ✅ | AB25: ACTUAL VS BUDGET | AF25: {=_xlfn.IFS( AH130-AG130<0,"UNDER BUDGET", AH130-AG130>0,"OVER BUDGET", AH130-AG130=0,"ON BUDGET ✅")} -> ON BUDGET ✅ | AG25: ACTUAL VS BUDGET
B28: Description | C28: ="Budget ("&'[1]Start Here'!$H$17&")" -> Budget ($) | D28: ="Actual ("&'[1]Start Here'!$H$17&")" -> Actual ($) | E28: ="Var. ("&'[1]Start Here'!$H$17&")" -> Var. ($) | G28: Description | H28: ="Budget ("&'[1]Start Here'!$H$17&")" -> Budget ($) | I28: ="Actual ("&'[1]Start Here'!$H$17&")" -> Actual ($) | J28: ="Var. ("&'[1]Start Here'!$H$17&")" -> Var. ($) | L28: Description | M28: ="Budget ("&'[1]Start Here'!$H$17&")" -> Budget ($) | N28: ="Actual ("&'[1]Start Here'!$H$17&")" -> Actual ($) | O28: ="Var. ("&'[1]Start Here'!$H$17&")" -> Var. ($) | Q28: Description | R28: ="Budget ("&'[1]Start Here'!$H$17&")" -> Budget ($) | S28: ="Actual ("&'[1]Start Here'!$H$17&")" -> Actual ($) | T28: ="Var. ("&'[1]Start Here'!$H$17&")" -> Var. ($) | V28: Description | W28: ="Budget ("&'[1]Start Here'!$H$17&")" -> Budget ($) | X28: ="Actual ("&'[1]Start Here'!$H$17&")" -> Actual ($) | Y28: ="Var. ("&'[1]Start Here'!$H$17&")" -> Var. ($) | AA28: Description | AB28: ="Budget ("&'[1]Start Here'!$H$17&")" -> Budget ($) | AC28: ="Actual ("&'[1]Start Here'!$H$17&")" -> Actual ($) | AD28: ="Var. ("&'[1]Start Here'!$H$17&")" -> Var. ($) | AF28: Description | AG28: ="Budget ("&'[1]Start Here'!$H$17&")" -> Budget ($) | AH28: ="Actual ("&'[1]Start Here'!$H$17&")" -> Actual ($) | AI28: ="Var. ("&'[1]Start Here'!$H$17&")" -> Var. ($)
D30: =IF(ISBLANK(C30),"",SUMIF($AN$5:$AN$1004,B30,$AO$5:$AO$1004)) | E30: =IF(ISBLANK(C30),"",D30-C30) | I30: =IF(ISBLANK(H30),"",SUMIF($AN$5:$AN$1004,G30,$AO$5:$AO$1004)) | J30: =IF(ISBLANK(H30),"",I30-H30) | N30: =IF(ISBLANK(M30),"",SUMIF($AN$5:$AN$1004,L30,$AO$5:$AO$1004)) | O30: =IF(ISBLANK(M30),"",N30-M30) | S30: =IF(ISBLANK(R30),"",SUMIF($AN$5:$AN$1004,Q30,$AO$5:$AO$1004)) | T30: =IF(ISBLANK(R30),"",S30-R30) | X30: =IF(ISBLANK(W30),"",SUMIF($AN$5:$AN$1004,V30,$AO$5:$AO$1004)) | Y30: =IF(ISBLANK(W30),"",X30-W30) | AC30: =IF(ISBLANK(AB30),"",SUMIF($AN$5:$AN$1004,AA30,$AO$5:$AO$1004)) | AD30: =IF(ISBLANK(AB30),"",AC30-AB30) | AH30: =IF(ISBLANK(AG30),"",SUMIF($AN$5:$AN$1004,AF30,$AO$5:$AO$1004)) | AI30: =IF(ISBLANK(AG30),"",AH30-AG30)
D31: =IF(ISBLANK(C31),"",SUMIF($AN$5:$AN$1004,B31,$AO$5:$AO$1004)) | E31: =IF(ISBLANK(C31),"",D31-C31) | I31: =IF(ISBLANK(H31),"",SUMIF($AN$5:$AN$1004,G31,$AO$5:$AO$1004)) | J31: =IF(ISBLANK(H31),"",I31-H31) | N31: =IF(ISBLANK(M31),"",SUMIF($AN$5:$AN$1004,L31,$AO$5:$AO$1004)) | O31: =IF(ISBLANK(M31),"",N31-M31) | S31: =IF(ISBLANK(R31),"",SUMIF($AN$5:$AN$1004,Q31,$AO$5:$AO$1004)) | T31: =IF(ISBLANK(R31),"",S31-R31) | X31: =IF(ISBLANK(W31),"",SUMIF($AN$5:$AN$1004,V31,$AO$5:$AO$1004)) | Y31: =IF(ISBLANK(W31),"",X31-W31) | AC31: =IF(ISBLANK(AB31),"",SUMIF($AN$5:$AN$1004,AA31,$AO$5:$AO$1004)) | AD31: =IF(ISBLANK(AB31),"",AC31-AB31) | AH31: =IF(ISBLANK(AG31),"",SUMIF($AN$5:$AN$1004,AF31,$AO$5:$AO$1004)) | AI31: =IF(ISBLANK(AG31),"",AH31-AG31)
D32: =IF(ISBLANK(C32),"",SUMIF($AN$5:$AN$1004,B32,$AO$5:$AO$1004)) | E32: =IF(ISBLANK(C32),"",D32-C32) | I32: =IF(ISBLANK(H32),"",SUMIF($AN$5:$AN$1004,G32,$AO$5:$AO$1004)) | J32: =IF(ISBLANK(H32),"",I32-H32) | N32: =IF(ISBLANK(M32),"",SUMIF($AN$5:$AN$1004,L32,$AO$5:$AO$1004)) | O32: =IF(ISBLANK(M32),"",N32-M32) | S32: =IF(ISBLANK(R32),"",SUMIF($AN$5:$AN$1004,Q32,$AO$5:$AO$1004)) | T32: =IF(ISBLANK(R32),"",S32-R32) | X32: =IF(ISBLANK(W32),"",SUMIF($AN$5:$AN$1004,V32,$AO$5:$AO$1004)) | Y32: =IF(ISBLANK(W32),"",X32-W32) | AC32: =IF(ISBLANK(AB32),"",SUMIF($AN$5:$AN$1004,AA32,$AO$5:$AO$1004)) | AD32: =IF(ISBLANK(AB32),"",AC32-AB32) | AH32: =IF(ISBLANK(AG32),"",SUMIF($AN$5:$AN$1004,AF32,$AO$5:$AO$1004)) | AI32: =IF(ISBLANK(AG32),"",AH32-AG32)
D33: =IF(ISBLANK(C33),"",SUMIF($AN$5:$AN$1004,B33,$AO$5:$AO$1004)) | E33: =IF(ISBLANK(C33),"",D33-C33) | I33: =IF(ISBLANK(H33),"",SUMIF($AN$5:$AN$1004,G33,$AO$5:$AO$1004)) | J33: =IF(ISBLANK(H33),"",I33-H33) | N33: =IF(ISBLANK(M33),"",SUMIF($AN$5:$AN$1004,L33,$AO$5:$AO$1004)) | O33: =IF(ISBLANK(M33),"",N33-M33) | S33: =IF(ISBLANK(R33),"",SUMIF($AN$5:$AN$1004,Q33,$AO$5:$AO$1004)) | T33: =IF(ISBLANK(R33),"",S33-R33) | X33: =IF(ISBLANK(W33),"",SUMIF($AN$5:$AN$1004,V33,$AO$5:$AO$1004)) | Y33: =IF(ISBLANK(W33),"",X33-W33) | AC33: =IF(ISBLANK(AB33),"",SUMIF($AN$5:$AN$1004,AA33,$AO$5:$AO$1004)) | AD33: =IF(ISBLANK(AB33),"",AC33-AB33) | AH33: =IF(ISBLANK(AG33),"",SUMIF($AN$5:$AN$1004,AF33,$AO$5:$AO$1004)) | AI33: =IF(ISBLANK(AG33),"",AH33-AG33)
D34: =IF(ISBLANK(C34),"",SUMIF($AN$5:$AN$1004,B34,$AO$5:$AO$1004)) | E34: =IF(ISBLANK(C34),"",D34-C34) | I34: =IF(ISBLANK(H34),"",SUMIF($AN$5:$AN$1004,G34,$AO$5:$AO$1004)) | J34: =IF(ISBLANK(H34),"",I34-H34) | N34: =IF(ISBLANK(M34),"",SUMIF($AN$5:$AN$1004,L34,$AO$5:$AO$1004)) | O34: =IF(ISBLANK(M34),"",N34-M34) | S34: =IF(ISBLANK(R34),"",SUMIF($AN$5:$AN$1004,Q34,$AO$5:$AO$1004)) | T34: =IF(ISBLANK(R34),"",S34-R34) | X34: =IF(ISBLANK(W34),"",SUMIF($AN$5:$AN$1004,V34,$AO$5:$AO$1004)) | Y34: =IF(ISBLANK(W34),"",X34-W34) | AC34: =IF(ISBLANK(AB34),"",SUMIF($AN$5:$AN$1004,AA34,$AO$5:$AO$1004)) | AD34: =IF(ISBLANK(AB34),"",AC34-AB34) | AH34: =IF(ISBLANK(AG34),"",SUMIF($AN$5:$AN$1004,AF34,$AO$5:$AO$1004)) | AI34: =IF(ISBLANK(AG34),"",AH34-AG34)
D35: =IF(ISBLANK(C35),"",SUMIF($AN$5:$AN$1004,B35,$AO$5:$AO$1004)) | E35: =IF(ISBLANK(C35),"",D35-C35) | I35: =IF(ISBLANK(H35),"",SUMIF($AN$5:$AN$1004,G35,$AO$5:$AO$1004)) | J35: =IF(ISBLANK(H35),"",I35-H35) | N35: =IF(ISBLANK(M35),"",SUMIF($AN$5:$AN$1004,L35,$AO$5:$AO$1004)) | O35: =IF(ISBLANK(M35),"",N35-M35) | S35: =IF(ISBLANK(R35),"",SUMIF($AN$5:$AN$1004,Q35,$AO$5:$AO$1004)) | T35: =IF(ISBLANK(R35),"",S35-R35) | X35: =IF(ISBLANK(W35),"",SUMIF($AN$5:$AN$1004,V35,$AO$5:$AO$1004)) | Y35: =IF(ISBLANK(W35),"",X35-W35) | AC35: =IF(ISBLANK(AB35),"",SUMIF($AN$5:$AN$1004,AA35,$AO$5:$AO$1004)) | AD35: =IF(ISBLANK(AB35),"",AC35-AB35) | AH35: =IF(ISBLANK(AG35),"",SUMIF($AN$5:$AN$1004,AF35,$AO$5:$AO$1004)) | AI35: =IF(ISBLANK(AG35),"",AH35-AG35)
D36: =IF(ISBLANK(C36),"",SUMIF($AN$5:$AN$1004,B36,$AO$5:$AO$1004)) | E36: =IF(ISBLANK(C36),"",D36-C36) | I36: =IF(ISBLANK(H36),"",SUMIF($AN$5:$AN$1004,G36,$AO$5:$AO$1004)) | J36: =IF(ISBLANK(H36),"",I36-H36) | N36: =IF(ISBLANK(M36),"",SUMIF($AN$5:$AN$1004,L36,$AO$5:$AO$1004)) | O36: =IF(ISBLANK(M36),"",N36-M36) | S36: =IF(ISBLANK(R36),"",SUMIF($AN$5:$AN$1004,Q36,$AO$5:$AO$1004)) | T36: =IF(ISBLANK(R36),"",S36-R36) | X36: =IF(ISBLANK(W36),"",SUMIF($AN$5:$AN$1004,V36,$AO$5:$AO$1004)) | Y36: =IF(ISBLANK(W36),"",X36-W36) | AC36: =IF(ISBLANK(AB36),"",SUMIF($AN$5:$AN$1004,AA36,$AO$5:$AO$1004)) | AD36: =IF(ISBLANK(AB36),"",AC36-AB36) | AH36: =IF(ISBLANK(AG36),"",SUMIF($AN$5:$AN$1004,AF36,$AO$5:$AO$1004)) | AI36: =IF(ISBLANK(AG36),"",AH36-AG36)
D37: =IF(ISBLANK(C37),"",SUMIF($AN$5:$AN$1004,B37,$AO$5:$AO$1004)) | E37: =IF(ISBLANK(C37),"",D37-C37) | I37: =IF(ISBLANK(H37),"",SUMIF($AN$5:$AN$1004,G37,$AO$5:$AO$1004)) | J37: =IF(ISBLANK(H37),"",I37-H37) | N37: =IF(ISBLANK(M37),"",SUMIF($AN$5:$AN$1004,L37,$AO$5:$AO$1004)) | O37: =IF(ISBLANK(M37),"",N37-M37) | S37: =IF(ISBLANK(R37),"",SUMIF($AN$5:$AN$1004,Q37,$AO$5:$AO$1004)) | T37: =IF(ISBLANK(R37),"",S37-R37) | X37: =IF(ISBLANK(W37),"",SUMIF($AN$5:$AN$1004,V37,$AO$5:$AO$1004)) | Y37: =IF(ISBLANK(W37),"",X37-W37) | AC37: =IF(ISBLANK(AB37),"",SUMIF($AN$5:$AN$1004,AA37,$AO$5:$AO$1004)) | AD37: =IF(ISBLANK(AB37),"",AC37-AB37) | AH37: =IF(ISBLANK(AG37),"",SUMIF($AN$5:$AN$1004,AF37,$AO$5:$AO$1004)) | AI37: =IF(ISBLANK(AG37),"",AH37-AG37)
D38: =IF(ISBLANK(C38),"",SUMIF($AN$5:$AN$1004,B38,$AO$5:$AO$1004)) | E38: =IF(ISBLANK(C38),"",D38-C38) | I38: =IF(ISBLANK(H38),"",SUMIF($AN$5:$AN$1004,G38,$AO$5:$AO$1004)) | J38: =IF(ISBLANK(H38),"",I38-H38) | N38: =IF(ISBLANK(M38),"",SUMIF($AN$5:$AN$1004,L38,$AO$5:$AO$1004)) | O38: =IF(ISBLANK(M38),"",N38-M38) | S38: =IF(ISBLANK(R38),"",SUMIF($AN$5:$AN$1004,Q38,$AO$5:$AO$1004)) | T38: =IF(ISBLANK(R38),"",S38-R38) | X38: =IF(ISBLANK(W38),"",SUMIF($AN$5:$AN$1004,V38,$AO$5:$AO$1004)) | Y38: =IF(ISBLANK(W38),"",X38-W38) | AC38: =IF(ISBLANK(AB38),"",SUMIF($AN$5:$AN$1004,AA38,$AO$5:$AO$1004)) | AD38: =IF(ISBLANK(AB38),"",AC38-AB38) | AH38: =IF(ISBLANK(AG38),"",SUMIF($AN$5:$AN$1004,AF38,$AO$5:$AO$1004)) | AI38: =IF(ISBLANK(AG38),"",AH38-AG38)
D39: =IF(ISBLANK(C39),"",SUMIF($AN$5:$AN$1004,B39,$AO$5:$AO$1004)) | E39: =IF(ISBLANK(C39),"",D39-C39) | I39: =IF(ISBLANK(H39),"",SUMIF($AN$5:$AN$1004,G39,$AO$5:$AO$1004)) | J39: =IF(ISBLANK(H39),"",I39-H39) | N39: =IF(ISBLANK(M39),"",SUMIF($AN$5:$AN$1004,L39,$AO$5:$AO$1004)) | O39: =IF(ISBLANK(M39),"",N39-M39) | S39: =IF(ISBLANK(R39),"",SUMIF($AN$5:$AN$1004,Q39,$AO$5:$AO$1004)) | T39: =IF(ISBLANK(R39),"",S39-R39) | X39: =IF(ISBLANK(W39),"",SUMIF($AN$5:$AN$1004,V39,$AO$5:$AO$1004)) | Y39: =IF(ISBLANK(W39),"",X39-W39) | AC39: =IF(ISBLANK(AB39),"",SUMIF($AN$5:$AN$1004,AA39,$AO$5:$AO$1004)) | AD39: =IF(ISBLANK(AB39),"",AC39-AB39) | AH39: =IF(ISBLANK(AG39),"",SUMIF($AN$5:$AN$1004,AF39,$AO$5:$AO$1004)) | AI39: =IF(ISBLANK(AG39),"",AH39-AG39)
D40: =IF(ISBLANK(C40),"",SUMIF($AN$5:$AN$1004,B40,$AO$5:$AO$1004)) | E40: =IF(ISBLANK(C40),"",D40-C40) | I40: =IF(ISBLANK(H40),"",SUMIF($AN$5:$AN$1004,G40,$AO$5:$AO$1004)) | J40: =IF(ISBLANK(H40),"",I40-H40) | N40: =IF(ISBLANK(M40),"",SUMIF($AN$5:$AN$1004,L40,$AO$5:$AO$1004)) | O40: =IF(ISBLANK(M40),"",N40-M40) | S40: =IF(ISBLANK(R40),"",SUMIF($AN$5:$AN$1004,Q40,$AO$5:$AO$1004)) | T40: =IF(ISBLANK(R40),"",S40-R40) | X40: =IF(ISBLANK(W40),"",SUMIF($AN$5:$AN$1004,V40,$AO$5:$AO$1004)) | Y40: =IF(ISBLANK(W40),"",X40-W40) | AC40: =IF(ISBLANK(AB40),"",SUMIF($AN$5:$AN$1004,AA40,$AO$5:$AO$1004)) | AD40: =IF(ISBLANK(AB40),"",AC40-AB40) | AH40: =IF(ISBLANK(AG40),"",SUMIF($AN$5:$AN$1004,AF40,$AO$5:$AO$1004)) | AI40: =IF(ISBLANK(AG40),"",AH40-AG40)
D41: =IF(ISBLANK(C41),"",SUMIF($AN$5:$AN$1004,B41,$AO$5:$AO$1004)) | E41: =IF(ISBLANK(C41),"",D41-C41) | I41: =IF(ISBLANK(H41),"",SUMIF($AN$5:$AN$1004,G41,$AO$5:$AO$1004)) | J41: =IF(ISBLANK(H41),"",I41-H41) | N41: =IF(ISBLANK(M41),"",SUMIF($AN$5:$AN$1004,L41,$AO$5:$AO$1004)) | O41: =IF(ISBLANK(M41),"",N41-M41) | S41: =IF(ISBLANK(R41),"",SUMIF($AN$5:$AN$1004,Q41,$AO$5:$AO$1004)) | T41: =IF(ISBLANK(R41),"",S41-R41) | X41: =IF(ISBLANK(W41),"",SUMIF($AN$5:$AN$1004,V41,$AO$5:$AO$1004)) | Y41: =IF(ISBLANK(W41),"",X41-W41) | AC41: =IF(ISBLANK(AB41),"",SUMIF($AN$5:$AN$1004,AA41,$AO$5:$AO$1004)) | AD41: =IF(ISBLANK(AB41),"",AC41-AB41) | AH41: =IF(ISBLANK(AG41),"",SUMIF($AN$5:$AN$1004,AF41,$AO$5:$AO$1004)) | AI41: =IF(ISBLANK(AG41),"",AH41-AG41)
... D129: =IF(ISBLANK(C129),"",SUMIF($AN$5:$AN$1004,B129,$AO$5:$AO$1004)) | E129: =IF(ISBLANK(C129),"",D129-C129) | I129: =IF(ISBLANK(H129),"",SUMIF($AN$5:$AN$1004,G129,$AO$5:$AO$1004)) | J129: =IF(ISBLANK(H129),"",I129-H129) | N129: =IF(ISBLANK(M129),"",SUMIF($AN$5:$AN$1004,L129,$AO$5:$AO$1004)) | O129: =IF(ISBLANK(M129),"",N129-M129) | S129: =IF(ISBLANK(R129),"",SUMIF($AN$5:$AN$1004,Q129,$AO$5:$AO$1004)) | T129: =IF(ISBLANK(R129),"",S129-R129) | X129: =IF(ISBLANK(W129),"",SUMIF($AN$5:$AN$1004,V129,$AO$5:$AO$1004)) | Y129: =IF(ISBLANK(W129),"",X129-W129) | AC129: =IF(ISBLANK(AB129),"",SUMIF($AN$5:$AN$1004,AA129,$AO$5:$AO$1004)) | AD129: =IF(ISBLANK(AB129),"",AC129-AB129) | AH129: =IF(ISBLANK(AG129),"",SUMIF($AN$5:$AN$1004,AF129,$AO$5:$AO$1004)) | AI129: =IF(ISBLANK(AG129),"",AH129-AG129)
B130: Total | C130: =SUM(C30:C129) -> 0 | D130: =SUM(D30:D129) -> 0 | E130: =SUM(E30:E129) -> 0 | G130: Total | H130: =SUM(H30:H129) -> 0 | I130: =SUM(I30:I129) -> 0 | J130: =IF(ISBLANK(H130),"",I130-H130) -> 0 | L130: Total | M130: =SUM(M30:M129) -> 0 | N130: =SUM(N30:N129) -> 0 | O130: =IF(ISBLANK(M130),"",N130-M130) -> 0 | Q130: Total | R130: =SUM(R30:R129) -> 0 | S130: =SUM(S30:S129) -> 0 | T130: =IF(ISBLANK(R130),"",S130-R130) -> 0 | V130: Total | W130: =SUM(W30:W129) -> 0 | X130: =SUM(X30:X129) -> 0 | Y130: =SUM(Y30:Y129) -> 0 | AA130: Total | AB130: =SUM(AB30:AB129) -> 0 | AC130: =SUM(AC30:AC129) -> 0 | AD130: =SUM(AD30:AD129) -> 0 | AF130: Total | AG130: =SUM(AG30:AG129) -> 0 | AH130: =SUM(AH30:AH129) -> 0 | AI130: =SUM(AI30:AI129) -> 0

Sheet 202507
B2: Season | C2: Summer
B4: =SUMIFS(D17:D90, C17:C90, "<=14") -> 922.03 | C4: Expenses: 1st to 15th
B5: =SUMIFS(D17:D90, C17:C90, ">=15") -> 4247.19 | C5: Expenses: 15th to 30th
B7: Description | C7: Expected Due Date | D7: Amount | G7: Description | H7: Expected Due Date | I7: Amount | J7: Adjusted Amount | K7: Adjusted Due Date
B8: CVS Income | C8: 15 | D8: 3500.73 | F8: =NOT(ISBLANK(C8)) -> TRUE | G8: {=_xlws.FILTER($B$8:$D$90, $F$8:$F$90)} -> #NAME? | J8: =IF(ISERROR(MATCH(G8, $B$8:$B$12, 0)), -1*I8,I8) -> 0 | K8: =DATE(2025, Cashflow!$D$2, $H8) -> 45930
B9: CVS Income | C9: 30 | D9: 3500.73 | F9: =NOT(ISBLANK(C9)) -> TRUE | J9: =IF(ISERROR(MATCH(G9, $B$8:$B$12, 0)), -1*I9,I9) -> 0 | K9: =DATE(2025, Cashflow!$D$2, $H9) -> 45930
B10: Apt 2 Rent | C10: 25 | F10: =NOT(ISBLANK(C10)) -> TRUE | J10: =IF(ISERROR(MATCH(G10, $B$8:$B$12, 0)), -1*I10,I10) -> 0 | K10: =DATE(2025, Cashflow!$D$2, $H10) -> 45930
B11: Apt 3 Rent | C11: 31 | F11: =NOT(ISBLANK(C11)) -> TRUE | J11: =IF(ISERROR(MATCH(G11, $B$8:$B$12, 0)), -1*I11,I11) -> 0 | K11: =DATE(2025, Cashflow!$D$2, $H11) -> 45930
B12: Uber Income | D12: 0 | F12: =NOT(ISBLANK(C12)) -> FALSE | J12: =IF(ISERROR(MATCH(G12, $B$8:$B$12, 0)), -1*I12,I12) -> 0 | K12: =DATE(2025, Cashflow!$D$2, $H12) -> 45930
F13: =NOT(ISBLANK(C13)) -> FALSE | J13: =IF(ISERROR(MATCH(G13, $B$8:$B$12, 0)), -1*I13,I13) -> 0 | K13: =DATE(2025, Cashflow!$D$2, $H13) -> 45930
B14: Total Income | D14: =SUM(D8:D12) -> 7001.46 | F14: =NOT(ISBLANK(C14)) -> FALSE | J14: =IF(ISERROR(MATCH(G14, $B$8:$B$12, 0)), -1*I14,I14) -> 0 | K14: =DATE(2025, Cashflow!$D$2, $H14) -> 45930
F15: =NOT(ISBLANK(C15)) -> FALSE | J15: =IF(ISERROR(MATCH(G15, $B$8:$B$12, 0)), -1*I15,I15) -> 0 | K15: =DATE(2025, Cashflow!$D$2, $H15) -> 45930
B16: Credit Cards | F16: =NOT(ISBLANK(C16)) -> FALSE | J16: =IF(ISERROR(MATCH(G16, $B$8:$B$12, 0)), -1*I16,I16) -> 0 | K16: =DATE(2025, Cashflow!$D$2, $H16) -> 45930
A17: FALSE | B17: BOA Customized Rewards | C17: 9 | D17: 35 | F17: =NOT(ISBLANK(C17)) -> TRUE | J17: =IF(ISERROR(MATCH(G17, $B$8:$B$12, 0)), -1*I17,I17) -> 0 | K17: =DATE(2025, Cashflow!$D$2, $H17) -> 45930
A18: FALSE | B18: BOA Unlimited Rewards | C18: 4 | D18: 25 | F18: =NOT(ISBLANK(C18)) -> TRUE | J18: =IF(ISERROR(MATCH(G18, $B$8:$B$12, 0)), -1*I18,I18) -> 0 | K18: =DATE(2025, Cashflow!$D$2, $H18) -> 45930
A19: FALSE | B19: CHASE Freedom | C19: 15 | D19: 440 | F19: =NOT(ISBLANK(C19)) -> TRUE | J19: =IF(ISERROR(MATCH(G19, $B$8:$B$12, 0)), -1*I19,I19) -> 0 | K19: =DATE(2025, Cashflow!$D$2, $H19) -> 45930
A20: FALSE | B20: CHASE Brittany | C20: 17 | D20: 125 | F20: =NOT(ISBLANK(C20)) -> TRUE | J20: =IF(ISERROR(MATCH(G20, $B$8:$B$12, 0)), -1*I20,I20) -> 0 | K20: =DATE(2025, Cashflow!$D$2, $H20) -> 45930
A21: FALSE | B21: CITI Diamond Preferred | C21: 15 | D21: 120 | F21: =NOT(ISBLANK(C21)) -> TRUE | J21: =IF(ISERROR(MATCH(G21, $B$8:$B$12, 0)), -1*I21,I21) -> 0 | K21: =DATE(2025, Cashflow!$D$2, $H21) -> 45930
A22: FALSE | B22: CITIZENS Clear Value | C22: 15 | D22: 70 | F22: =NOT(ISBLANK(C22)) -> TRUE | J22: =IF(ISERROR(MATCH(G22, $B$8:$B$12, 0)), -1*I22,I22) -> 0 | K22: =DATE(2025, Cashflow!$D$2, $H22) -> 45930
F23: =NOT(ISBLANK(C23)) -> FALSE | J23: =IF(ISERROR(MATCH(G23, $B$8:$B$12, 0)), -1*I23,I23) -> 0 | K23: =DATE(2025, Cashflow!$D$2, $H23) -> 45930
B24: Loan Payments | F24: =NOT(ISBLANK(C24)) -> FALSE | J24: =IF(ISERROR(MATCH(G24, $B$8:$B$12, 0)), -1*I24,I24) -> 0 | K24: =DATE(2025, Cashflow!$D$2, $H24) -> 45930
A25: FALSE | B25: CITIZENS Mortgage | C25: 1 | D25: 0 | F25: =NOT(ISBLANK(C25)) -> TRUE | J25: =IF(ISERROR(MATCH(G25, $B$8:$B$12, 0)), -1*I25,I25) -> 0 | K25: =DATE(2025, Cashflow!$D$2, $H25) -> 45930
A26: FALSE | B26: UPSTART Debt Consolidation | C26: 15 | D26: 181.13 | F26: =NOT(ISBLANK(C26)) -> TRUE | J26: =IF(ISERROR(MATCH(G26, $B$8:$B$12, 0)), -1*I26,I26) -> 0 | K26: =DATE(2025, Cashflow!$D$2, $H26) -> 45930
A27: FALSE | B27: LIGHTSTREAM Renovation | C27: 15 | D27: 525.13 | F27: =NOT(ISBLANK(C27)) -> TRUE | J27: =IF(ISERROR(MATCH(G27, $B$8:$B$12, 0)), -1*I27,I27) -> 0 | K27: =DATE(2025, Cashflow!$D$2, $H27) -> 45930
A28: FALSE | B28: AFFIRM Photography | C28: 21 | D28: 235.17 | F28: =NOT(ISBLANK(C28)) -> TRUE | J28: =IF(ISERROR(MATCH(G28, $B$8:$B$12, 0)), -1*I28,I28) -> 0 | K28: =DATE(2025, Cashflow!$D$2, $H28) -> 45930
A29: FALSE | B29: AQUA FINANCE Roofing Replacement | D29: 268.44 | F29: =NOT(ISBLANK(C29)) -> FALSE | J29: =IF(ISERROR(MATCH(G29, $B$8:$B$12, 0)), -1*I29,I29) -> 0 | K29: =DATE(2025, Cashflow!$D$2, $H29) -> 45930
A30: FALSE | B30: CONNEX Auto Loan | C30: 17 | D30: 878.54 | F30: =NOT(ISBLANK(C30)) -> TRUE | J30: =IF(ISERROR(MATCH(G30, $B$8:$B$12, 0)), -1*I30,I30) -> 0 | K30: =DATE(2025, Cashflow!$D$2, $H30) -> 45930
A31: FALSE | B31: NELNET Student Loans | F31: =NOT(ISBLANK(C31)) -> FALSE | J31: =IF(ISERROR(MATCH(G31, $B$8:$B$12, 0)), -1*I31,I31) -> 0 | K31: =DATE(2025, Cashflow!$D$2, $H31) -> 45930
F32: =NOT(ISBLANK(C32)) -> FALSE | J32: =IF(ISERROR(MATCH(G32, $B$8:$B$12, 0)), -1*I32,I32) -> 0 | K32: =DATE(2025, Cashflow!$D$2, $H32) -> 45930
B33: Propery Expenses | F33: =NOT(ISBLANK(C33)) -> FALSE | J33: =IF(ISERROR(MATCH(G33, $B$8:$B$12, 0)), -1*I33,I33) -> 0 | K33: =DATE(2025, Cashflow!$D$2, $H33) -> 45930
A34: FALSE | B34: Owner Contribution to Mortgage | C34: 1 | D34: 153.54 | F34: =NOT(ISBLANK(C34)) -> TRUE | J34: =IF(ISERROR(MATCH(G34, $B$8:$B$12, 0)), -1*I34,I34) -> 0 | K34: =DATE(2025, Cashflow!$D$2, $H34) -> 45930
A35: FALSE | B35: Landlord Electricity | C35: 5 | D35: 40 | F35: =NOT(ISBLANK(C35)) -> TRUE | J35: =IF(ISERROR(MATCH(G35, $B$8:$B$12, 0)), -1*I35,I35) -> 0 | K35: =DATE(2025, Cashflow!$D$2, $H35) -> 45930
A36: FALSE | B36: Water/Sewer (Monthly) | D36: 130 | F36: =NOT(ISBLANK(C36)) -> FALSE | J36: =IF(ISERROR(MATCH(G36, $B$8:$B$12, 0)), -1*I36,I36) -> 0 | K36: =DATE(2025, Cashflow!$D$2, $H36) -> 45930
A37: FALSE | B37: Maintenance (Lawn) | D37: =IF($C$2="Summer", 80, 0) -> 80 | F37: =NOT(ISBLANK(C37)) -> FALSE | J37: =IF(ISERROR(MATCH(G37, $B$8:$B$12, 0)), -1*I37,I37) -> 0 | K37: =DATE(2025, Cashflow!$D$2, $H37) -> 45930
A38: FALSE | B38: Maintenance (Snow Removal) | D38: =IF($C$2="Winter", 110, 0) -> 0 | F38: =NOT(ISBLANK(C38)) -> FALSE | J38: =IF(ISERROR(MATCH(G38, $B$8:$B$12, 0)), -1*I38,I38) -> 0 | K38: =DATE(2025, Cashflow!$D$2, $H38) -> 45930
A39: FALSE | B39: Blink Security | C39: 5 | D39: 10.64 | F39: =NOT(ISBLANK(C39)) -> TRUE | J39: =IF(ISERROR(MATCH(G39, $B$8:$B$12, 0)), -1*I39,I39) -> 0 | K39: =DATE(2025, Cashflow!$D$2, $H39) -> 45930
A40: FALSE | B40: Avail Portal | C40: 16 | D40: 18 | F40: =NOT(ISBLANK(C40)) -> TRUE | J40: =IF(ISERROR(MATCH(G40, $B$8:$B$12, 0)), -1*I40,I40) -> 0 | K40: =DATE(2025, Cashflow!$D$2, $H40) -> 45930
F41: =NOT(ISBLANK(C41)) -> FALSE | J41: =IF(ISERROR(MATCH(G41, $B$8:$B$12, 0)), -1*I41,I41) -> 0 | K41: =DATE(2025, Cashflow!$D$2, $H41) -> 45930
B42: Bills | F42: =NOT(ISBLANK(C42)) -> FALSE | J42: =IF(ISERROR(MATCH(G42, $B$8:$B$12, 0)), -1*I42,I42) -> 0 | K42: =DATE(2025, Cashflow!$D$2, $H42) -> 45930
A43: FALSE | B43: Auto Insurance | C43: 5 | D43: 95 | F43: =NOT(ISBLANK(C43)) -> TRUE | J43: =IF(ISERROR(MATCH(G43, $B$8:$B$12, 0)), -1*I43,I43) -> 0 | K43: =DATE(2025, Cashflow!$D$2, $H43) -> 45930
...

Sheet 202508
B2: Season | C2: Summer
B4: =SUMIFS(D17:D94, C17:C94, "<=14") -> 1310.34 | C4: Expenses: 1st to 15th
B5: =SUMIFS(D17:D94, C17:C94, ">=15") -> 4864.44 | C5: Expenses: 15th to 30th
P6: =SUM(P7:P50) -> -350.71
B7: Description | C7: Expected Due Date | D7: Amount | G7: Description | H7: Expected Due Date | I7: Amount | J7: Adjusted Amount | K7: Adjusted Due Date | O7: New Britain Water Bill | P7: 0 | Q7: 795.49
B8: CVS Income | C8: 15 | D8: 3500.73 | F8: =NOT(ISBLANK(C8)) -> TRUE | G8: =IFERROR(__xludf.DUMMYFUNCTION("FILTER($B$8:$D$94, $F$8:$F$94)"),"CVS Income") -> CVS Income | H8: =IFERROR(__xludf.DUMMYFUNCTION("""COMPUTED_VALUE"""),15) -> 15 | I8: =IFERROR(__xludf.DUMMYFUNCTION("""COMPUTED_VALUE"""),3500.73) -> 3500.73 | J8: =IF(ISERROR(MATCH(G8, $B$8:$B$12, 0)), -1*I8,I8) -> 3500.73 | K8: =DATE(2025, Cashflow!$D$2, $H8) -> 45945 | O8: New Britain Auto Tax | P8: 773.71
B9: CVS Income | C9: 30 | D9: 3500.73 | F9: =NOT(ISBLANK(C9)) -> TRUE | G9: =IFERROR(__xludf.DUMMYFUNCTION("""COMPUTED_VALUE"""),"CVS Income") -> CVS Income | H9: =IFERROR(__xludf.DUMMYFUNCTION("""COMPUTED_VALUE"""),30) -> 30 | I9: =IFERROR(__xludf.DUMMYFUNCTION("""COMPUTED_VALUE"""),3500.73) -> 3500.73 | J9: =IF(ISERROR(MATCH(G9, $B$8:$B$12, 0)), -1*I9,I9) -> 3500.73 | K9: =DATE(2025, Cashflow!$D$2, $H9) -> 45960 | O9: Prism Q1 | P9: 682.5
B10: Apt 2 Rent | C10: 25 | F10: =NOT(ISBLANK(C10)) -> TRUE | G10: =IFERROR(__xludf.DUMMYFUNCTION("""COMPUTED_VALUE"""),"Apt 2 Rent") -> Apt 2 Rent | H10: =IFERROR(__xludf.DUMMYFUNCTION("""COMPUTED_VALUE"""),25) -> 25 | J10: =IF(ISERROR(MATCH(G10, $B$8:$B$12, 0)), -1*I10,I10) -> 0 | K10: =DATE(2025, Cashflow!$D$2, $H10) -> 45955 | O10: Connecticut Children
B11: Apt 3 Rent | C11: 31 | F11: =NOT(ISBLANK(C11)) -> TRUE | G11: =IFERROR(__xludf.DUMMYFUNCTION("""COMPUTED_VALUE"""),"Apt 3 Rent") -> Apt 3 Rent | H11: =IFERROR(__xludf.DUMMYFUNCTION("""COMPUTED_VALUE"""),31) -> 31 | J11: =IF(ISERROR(MATCH(G11, $B$8:$B$12, 0)), -1*I11,I11) -> 0 | K11: =DATE(2025, Cashflow!$D$2, $H11) -> 45961 | O11: Connecticut Children | P11: 2303.67
B12: Uber Income | D12: 0 | F12: =NOT(ISBLANK(C12)) -> FALSE | G12: =IFERROR(__xludf.DUMMYFUNCTION("""COMPUTED_VALUE"""),"BOA Customized Rewards") -> BOA Customized Rewards | H12: =IFERROR(__xludf.DUMMYFUNCTION("""COMPUTED_VALUE"""),9) -> 9 | I12: =IFERROR(__xludf.DUMMYFUNCTION("""COMPUTED_VALUE"""),61) -> 61 | J12: =IF(ISERROR(MATCH(G12, $B$8:$B$12, 0)), -1*I12,I12) -> -61 | K12: =DATE(2025, Cashflow!$D$2, $H12) -> 45939 | O12: Affirm | P12: 464.43
F13: =NOT(ISBLANK(C13)) -> FALSE | G13: =IFERROR(__xludf.DUMMYFUNCTION("""COMPUTED_VALUE"""),"BOA Unlimited Rewards") -> BOA Unlimited Rewards | H13: =IFERROR(__xludf.DUMMYFUNCTION("""COMPUTED_VALUE"""),4) -> 4 | I13: =IFERROR(__xludf.DUMMYFUNCTION("""COMPUTED_VALUE"""),35) -> 35 | J13: =IF(ISERROR(MATCH(G13, $B$8:$B$12, 0)), -1*I13,I13) -> -35 | K13: =DATE(2025, Cashflow!$D$2, $H13) -> 45934
B14: Total Income | D14: =SUM(D8:D12) -> 7001.46 | F14: =NOT(ISBLANK(C14)) -> FALSE | G14: =IFERROR(__xludf.DUMMYFUNCTION("""COMPUTED_VALUE"""),"CHASE Freedom") -> CHASE Freedom | H14: =IFERROR(__xludf.DUMMYFUNCTION("""COMPUTED_VALUE"""),15) -> 15 | I14: =IFERROR(__xludf.DUMMYFUNCTION("""COMPUTED_VALUE"""),440) -> 440 | J14: =IF(ISERROR(MATCH(G14, $B$8:$B$12, 0)), -1*I14,I14) -> -440 | K14: =DATE(2025, Cashflow!$D$2, $H14) -> 45945 | O14: Home Depot | P14: 576.78
F15: =NOT(ISBLANK(C15)) -> FALSE | G15: =IFERROR(__xludf.DUMMYFUNCTION("""COMPUTED_VALUE"""),"CHASE Brittany") -> CHASE Brittany | H15: =IFERROR(__xludf.DUMMYFUNCTION("""COMPUTED_VALUE"""),17) -> 17 | I15: =IFERROR(__xludf.DUMMYFUNCTION("""COMPUTED_VALUE"""),125) -> 125 | J15: =IF(ISERROR(MATCH(G15, $B$8:$B$12, 0)), -1*I15,I15) -> -125 | K15: =DATE(2025, Cashflow!$D$2, $H15) -> 45947
B16: Credit Cards | F16: =NOT(ISBLANK(C16)) -> FALSE | G16: =IFERROR(__xludf.DUMMYFUNCTION("""COMPUTED_VALUE"""),"CITI Diamond Preferred") -> CITI Diamond Preferred | H16: =IFERROR(__xludf.DUMMYFUNCTION("""COMPUTED_VALUE"""),15) -> 15 | I16: =IFERROR(__xludf.DUMMYFUNCTION("""COMPUTED_VALUE"""),120) -> 120 | J16: =IF(ISERROR(MATCH(G16, $B$8:$B$12, 0)), -1*I16,I16) -> -120 | K16: =DATE(2025, Cashflow!$D$2, $H16) -> 45945 | O16: Dividend Cash | P16: -571.45
A17: TRUE | B17: BOA Customized Rewards | C17: 9 | D17: 61 | F17: =NOT(ISBLANK(C17)) -> TRUE | G17: =IFERROR(__xludf.DUMMYFUNCTION("""COMPUTED_VALUE"""),"CITIZENS Clear Value") -> CITIZENS Clear Value | H17: =IFERROR(__xludf.DUMMYFUNCTION("""COMPUTED_VALUE"""),13) -> 13 | I17: =IFERROR(__xludf.DUMMYFUNCTION("""COMPUTED_VALUE"""),64) -> 64 | J17: =IF(ISERROR(MATCH(G17, $B$8:$B$12, 0)), -1*I17,I17) -> -64 | K17: =DATE(2025, Cashflow!$D$2, $H17) -> 45943 | O17: Sold Qualifying Stock | P17: -4580.35
A18: TRUE | B18: BOA Unlimited Rewards | C18: 4 | D18: 35 | F18: =NOT(ISBLANK(C18)) -> TRUE | G18: =IFERROR(__xludf.DUMMYFUNCTION("""COMPUTED_VALUE"""),"CITIZENS Mortgage") -> CITIZENS Mortgage | H18: =IFERROR(__xludf.DUMMYFUNCTION("""COMPUTED_VALUE"""),1) -> 1 | I18: =IFERROR(__xludf.DUMMYFUNCTION("""COMPUTED_VALUE"""),0) -> 0 | J18: =IF(ISERROR(MATCH(G18, $B$8:$B$12, 0)), -1*I18,I18) -> 0 | K18: =DATE(2025, Cashflow!$D$2, $H18) -> 45931
A19: FALSE | B19: CHASE Freedom | C19: 15 | D19: 440 | F19: =NOT(ISBLANK(C19)) -> TRUE | G19: =IFERROR(__xludf.DUMMYFUNCTION("""COMPUTED_VALUE"""),"UPSTART Debt Consolidation") -> UPSTART Debt Consolidation | H19: =IFERROR(__xludf.DUMMYFUNCTION("""COMPUTED_VALUE"""),15) -> 15 | I19: =IFERROR(__xludf.DUMMYFUNCTION("""COMPUTED_VALUE"""),181.13) -> 181.13 | J19: =IF(ISERROR(MATCH(G19, $B$8:$B$12, 0)), -1*I19,I19) -> -181.13 | K19: =DATE(2025, Cashflow!$D$2, $H19) -> 45945
A20: FALSE | B20: CHASE Brittany | C20: 17 | D20: 125 | F20: =NOT(ISBLANK(C20)) -> TRUE | G20: =IFERROR(__xludf.DUMMYFUNCTION("""COMPUTED_VALUE"""),"LIGHTSTREAM Renovation") -> LIGHTSTREAM Renovation | H20: =IFERROR(__xludf.DUMMYFUNCTION("""COMPUTED_VALUE"""),15) -> 15 | I20: =IFERROR(__xludf.DUMMYFUNCTION("""COMPUTED_VALUE"""),525.13) -> 525.13 | J20: =IF(ISERROR(MATCH(G20, $B$8:$B$12, 0)), -1*I20,I20) -> -525.13 | K20: =DATE(2025, Cashflow!$D$2, $H20) -> 45945
A21: FALSE | B21: CITI Diamond Preferred | C21: 15 | D21: 120 | F21: =NOT(ISBLANK(C21)) -> TRUE | G21: =IFERROR(__xludf.DUMMYFUNCTION("""COMPUTED_VALUE"""),"AFFIRM Photography") -> AFFIRM Photography | H21: =IFERROR(__xludf.DUMMYFUNCTION("""COMPUTED_VALUE"""),21) -> 21 | I21: =IFERROR(__xludf.DUMMYFUNCTION("""COMPUTED_VALUE"""),235.17) -> 235.17 | J21: =IF(ISERROR(MATCH(G21, $B$8:$B$12, 0)), -1*I21,I21) -> -235.17 | K21: =DATE(2025, Cashflow!$D$2, $H21) -> 45951
A22: TRUE | B22: CITIZENS Clear Value | C22: 13 | D22: 64 | F22: =NOT(ISBLANK(C22)) -> TRUE | G22: =IFERROR(__xludf.DUMMYFUNCTION("""COMPUTED_VALUE"""),"CONNEX Auto Loan") -> CONNEX Auto Loan | H22: =IFERROR(__xludf.DUMMYFUNCTION("""COMPUTED_VALUE"""),17) -> 17 | I22: =IFERROR(__xludf.DUMMYFUNCTION("""COMPUTED_VALUE"""),878.54) -> 878.54 | J22: =IF(ISERROR(MATCH(G22, $B$8:$B$12, 0)), -1*I22,I22) -> -878.54 | K22: =DATE(2025, Cashflow!$D$2, $H22) -> 45947
F23: =NOT(ISBLANK(C23)) -> FALSE | G23: =IFERROR(__xludf.DUMMYFUNCTION("""COMPUTED_VALUE"""),"Owner Contribution to Mortgage") -> Owner Contribution to Mortgage | H23: =IFERROR(__xludf.DUMMYFUNCTION("""COMPUTED_VALUE"""),1) -> 1 | I23: =IFERROR(__xludf.DUMMYFUNCTION("""COMPUTED_VALUE"""),146.54) -> 146.54 | J23: =IF(ISERROR(MATCH(G23, $B$8:$B$12, 0)), -1*I23,I23) -> -146.54 | K23: =DATE(2025, Cashflow!$D$2, $H23) -> 45931
B24: Loan Payments | F24: =NOT(ISBLANK(C24)) -> FALSE | G24: =IFERROR(__xludf.DUMMYFUNCTION("""COMPUTED_VALUE"""),"Landlord Electricity") -> Landlord Electricity | H24: =IFERROR(__xludf.DUMMYFUNCTION("""COMPUTED_VALUE"""),18) -> 18 | I24: =IFERROR(__xludf.DUMMYFUNCTION("""COMPUTED_VALUE"""),33.16) -> 33.16 | J24: =IF(ISERROR(MATCH(G24, $B$8:$B$12, 0)), -1*I24,I24) -> -33.16 | K24: =DATE(2025, Cashflow!$D$2, $H24) -> 45948
A25: TRUE | B25: CITIZENS Mortgage | C25: 1 | D25: 0 | F25: =NOT(ISBLANK(C25)) -> TRUE | G25: =IFERROR(__xludf.DUMMYFUNCTION("""COMPUTED_VALUE"""),"Maintenance (Lawn)") -> Maintenance (Lawn) | H25: =IFERROR(__xludf.DUMMYFUNCTION("""COMPUTED_VALUE"""),1) -> 1 | I25: =IFERROR(__xludf.DUMMYFUNCTION("""COMPUTED_VALUE"""),80) -> 80 | J25: =IF(ISERROR(MATCH(G25, $B$8:$B$12, 0)), -1*I25,I25) -> -80 | K25: =DATE(2025, Cashflow!$D$2, $H25) -> 45931
A26: FALSE | B26: UPSTART Debt Consolidation | C26: 15 | D26: 181.13 | F26: =NOT(ISBLANK(C26)) -> TRUE | G26: =IFERROR(__xludf.DUMMYFUNCTION("""COMPUTED_VALUE"""),"Maintenance (Lawn)") -> Maintenance (Lawn) | H26: =IFERROR(__xludf.DUMMYFUNCTION("""COMPUTED_VALUE"""),15) -> 15 | I26: =IFERROR(__xludf.DUMMYFUNCTION("""COMPUTED_VALUE"""),80) -> 80 | J26: =IF(ISERROR(MATCH(G26, $B$8:$B$12, 0)), -1*I26,I26) -> -80 | K26: =DATE(2025, Cashflow!$D$2, $H26) -> 45945
A27: FALSE | B27: LIGHTSTREAM Renovation | C27: 15 | D27: 525.13 | F27: =NOT(ISBLANK(C27)) -> TRUE | G27: =IFERROR(__xludf.DUMMYFUNCTION("""COMPUTED_VALUE"""),"Maintenance (Lawn)") -> Maintenance (Lawn) | H27: =IFERROR(__xludf.DUMMYFUNCTION("""COMPUTED_VALUE"""),29) -> 29 | I27: =IFERROR(__xludf.DUMMYFUNCTION("""COMPUTED_VALUE"""),80) -> 80 | J27: =IF(ISERROR(MATCH(G27, $B$8:$B$12, 0)), -1*I27,I27) -> -80 | K27: =DATE(2025, Cashflow!$D$2, $H27) -> 45959
A28: FALSE | B28: AFFIRM Photography | C28: 21 | D28: 235.17 | F28: =NOT(ISBLANK(C28)) -> TRUE | G28: =IFERROR(__xludf.DUMMYFUNCTION("""COMPUTED_VALUE"""),"Blink Security") -> Blink Security | H28: =IFERROR(__xludf.DUMMYFUNCTION("""COMPUTED_VALUE"""),5) -> 5 | I28: =IFERROR(__xludf.DUMMYFUNCTION("""COMPUTED_VALUE"""),10.64) -> 10.64 | J28: =IF(ISERROR(MATCH(G28, $B$8:$B$12, 0)), -1*I28,I28) -> -10.64 | K28: =DATE(2025, Cashflow!$D$2, $H28) -> 45935
A29: FALSE | B29: AQUA FINANCE Roofing Replacement | D29: 268.44 | F29: =NOT(ISBLANK(C29)) -> FALSE | G29: =IFERROR(__xludf.DUMMYFUNCTION("""COMPUTED_VALUE"""),"Avail Portal") -> Avail Portal | H29: =IFERROR(__xludf.DUMMYFUNCTION("""COMPUTED_VALUE"""),16) -> 16 | I29: =IFERROR(__xludf.DUMMYFUNCTION("""COMPUTED_VALUE"""),18) -> 18 | J29: =IF(ISERROR(MATCH(G29, $B$8:$B$12, 0)), -1*I29,I29) -> -18 | K29: =DATE(2025, Cashflow!$D$2, $H29) -> 45946
A30: FALSE | B30: CONNEX Auto Loan | C30: 17 | D30: 878.54 | F30: =NOT(ISBLANK(C30)) -> TRUE | G30: =IFERROR(__xludf.DUMMYFUNCTION("""COMPUTED_VALUE"""),"Auto Insurance") -> Auto Insurance | H30: =IFERROR(__xludf.DUMMYFUNCTION("""COMPUTED_VALUE"""),4) -> 4 | I30: =IFERROR(__xludf.DUMMYFUNCTION("""COMPUTED_VALUE"""),243.49) -> 243.49 | J30: =IF(ISERROR(MATCH(G30, $B$8:$B$12, 0)), -1*I30,I30) -> -243.49 | K30: =DATE(2025, Cashflow!$D$2, $H30) -> 45934
A31: FALSE | B31: NELNET Student Loans | F31: =NOT(ISBLANK(C31)) -> FALSE | G31: =IFERROR(__xludf.DUMMYFUNCTION("""COMPUTED_VALUE"""),"Auto Taxes (Monthly)") -> Auto Taxes (Monthly) | H31: =IFERROR(__xludf.DUMMYFUNCTION("""COMPUTED_VALUE"""),1) -> 1 | I31: =IFERROR(__xludf.DUMMYFUNCTION("""COMPUTED_VALUE"""),0) -> 0 | J31: =IF(ISERROR(MATCH(G31, $B$8:$B$12, 0)), -1*I31,I31) -> 0 | K31: =DATE(2025, Cashflow!$D$2, $H31) -> 45931
F32: =NOT(ISBLANK(C32)) -> FALSE | G32: =IFERROR(__xludf.DUMMYFUNCTION("""COMPUTED_VALUE"""),"Heating/Natural Gas") -> Heating/Natural Gas | H32: =IFERROR(__xludf.DUMMYFUNCTION("""COMPUTED_VALUE"""),23) -> 23 | I32: =IFERROR(__xludf.DUMMYFUNCTION("""COMPUTED_VALUE"""),260.73) -> 260.73 | J32: =IF(ISERROR(MATCH(G32, $B$8:$B$12, 0)), -1*I32,I32) -> -260.73 | K32: =DATE(2025, Cashflow!$D$2, $H32) -> 45953
B33: Propery Expenses | F33: =NOT(ISBLANK(C33)) -> FALSE | G33: =IFERROR(__xludf.DUMMYFUNCTION("""COMPUTED_VALUE"""),"Electricity") -> Electricity | H33: =IFERROR(__xludf.DUMMYFUNCTION("""COMPUTED_VALUE"""),18) -> 18 | I33: =IFERROR(__xludf.DUMMYFUNCTION("""COMPUTED_VALUE"""),199.07) -> 199.07 | J33: =IF(ISERROR(MATCH(G33, $B$8:$B$12, 0)), -1*I33,I33) -> -199.07 | K33: =DATE(2025, Cashflow!$D$2, $H33) -> 45948
A34: TRUE | B34: Owner Contribution to Mortgage | C34: 1 | D34: 146.54 | F34: =NOT(ISBLANK(C34)) -> TRUE | G34: =IFERROR(__xludf.DUMMYFUNCTION("""COMPUTED_VALUE"""),"Internet") -> Internet | H34: =IFERROR(__xludf.DUMMYFUNCTION("""COMPUTED_VALUE"""),28) -> 28 | I34: =IFERROR(__xludf.DUMMYFUNCTION("""COMPUTED_VALUE"""),74.95) -> 74.95 | J34: =IF(ISERROR(MATCH(G34, $B$8:$B$12, 0)), -1*I34,I34) -> -74.95 | K34: =DATE(2025, Cashflow!$D$2, $H34) -> 45958
A35: FALSE | B35: Landlord Electricity | C35: 18 | D35: 33.16 | F35: =NOT(ISBLANK(C35)) -> TRUE | G35: =IFERROR(__xludf.DUMMYFUNCTION("""COMPUTED_VALUE"""),"Life Insurance") -> Life Insurance | H35: =IFERROR(__xludf.DUMMYFUNCTION("""COMPUTED_VALUE"""),16) -> 16 | I35: =IFERROR(__xludf.DUMMYFUNCTION("""COMPUTED_VALUE"""),82.37) -> 82.37 | J35: =IF(ISERROR(MATCH(G35, $B$8:$B$12, 0)), -1*I35,I35) -> -82.37 | K35: =DATE(2025, Cashflow!$D$2, $H35) -> 45946
A36: FALSE | B36: Water/Sewer (Monthly) | D36: 130 | F36: =NOT(ISBLANK(C36)) -> FALSE | G36: =IFERROR(__xludf.DUMMYFUNCTION("""COMPUTED_VALUE"""),"Groceries + Toiletries") -> Groceries + Toiletries | H36: =IFERROR(__xludf.DUMMYFUNCTION("""COMPUTED_VALUE"""),1) -> 1 | I36: =IFERROR(__xludf.DUMMYFUNCTION("""COMPUTED_VALUE"""),252.58) -> 252.58 | J36: =IF(ISERROR(MATCH(G36, $B$8:$B$12, 0)), -1*I36,I36) -> -252.58 | K36: =DATE(2025, Cashflow!$D$2, $H36) -> 45931
A37: TRUE | B37: Maintenance (Lawn) | C37: 1 | D37: =IF($C$2="Summer", 80, 0) -> 80 | F37: =NOT(ISBLANK(C37)) -> TRUE | G37: =IFERROR(__xludf.DUMMYFUNCTION("""COMPUTED_VALUE"""),"Groceries + Toiletries") -> Groceries + Toiletries | H37: =IFERROR(__xludf.DUMMYFUNCTION("""COMPUTED_VALUE"""),8) -> 8 | I37: =IFERROR(__xludf.DUMMYFUNCTION("""COMPUTED_VALUE"""),248.95) -> 248.95 | J37: =IF(ISERROR(MATCH(G37, $B$8:$B$12, 0)), -1*I37,I37) -> -248.95 | K37: =DATE(2025, Cashflow!$D$2, $H37) -> 45938
A38: FALSE | B38: Maintenance (Lawn) | C38: 15 | D38: =IF($C$2="Summer", 80, 0) -> 80 | F38: =NOT(ISBLANK(C38)) -> TRUE | G38: =IFERROR(__xludf.DUMMYFUNCTION("""COMPUTED_VALUE"""),"Groceries + Toiletries") -> Groceries + Toiletries | H38: =IFERROR(__xludf.DUMMYFUNCTION("""COMPUTED_VALUE"""),15) -> 15 | I38: =IFERROR(__xludf.DUMMYFUNCTION("""COMPUTED_VALUE"""),250) -> 250 | J38: =IF(ISERROR(MATCH(G38, $B$8:$B$12, 0)), -1*I38,I38) -> -250 | K38: =DATE(2025, Cashflow!$D$2, $H38) -> 45945
A39: FALSE | B39: Maintenance (Lawn) | C39: 29 | D39: =IF($C$2="Summer", 80, 0) -> 80 | F39: =NOT(ISBLANK(C39)) -> TRUE | G39: =IFERROR(__xludf.DUMMYFUNCTION("""COMPUTED_VALUE"""),"Groceries + Toiletries") -> Groceries + Toiletries | H39: =IFERROR(__xludf.DUMMYFUNCTION("""COMPUTED_VALUE"""),22) -> 22 | I39: =IFERROR(__xludf.DUMMYFUNCTION("""COMPUTED_VALUE"""),250) -> 250 | J39: =IF(ISERROR(MATCH(G39, $B$8:$B$12, 0)), -1*I39,I39) -> -250 | K39: =DATE(2025, Cashflow!$D$2, $H39) -> 45952
A40: TRUE | B40: Maintenance (Snow Removal) | D40: =IF($C$2="Winter", 110, 0) -> 0 | F40: =NOT(ISBLANK(C40)) -> FALSE | G40: =IFERROR(__xludf.DUMMYFUNCTION("""COMPUTED_VALUE"""),"Groceries + Toiletries") -> Groceries + Toiletries | H40: =IFERROR(__xludf.DUMMYFUNCTION("""COMPUTED_VALUE"""),29) -> 29 | I40: =IFERROR(__xludf.DUMMYFUNCTION("""COMPUTED_VALUE"""),250) -> 250 | J40: =IF(ISERROR(MATCH(G40, $B$8:$B$12, 0)), -1*I40,I40) -> -250 | K40: =DATE(2025, Cashflow!$D$2, $H40) -> 45959
A41: TRUE | B41: Blink Security | C41: 5 | D41: 10.64 | F41: =NOT(ISBLANK(C41)) -> TRUE | G41: =IFERROR(__xludf.DUMMYFUNCTION("""COMPUTED_VALUE"""),"Phone (Nykosi)") -> Phone (Nykosi) | H41: =IFERROR(__xludf.DUMMYFUNCTION("""COMPUTED_VALUE"""),16) -> 16 | I41: =IFERROR(__xludf.DUMMYFUNCTION("""COMPUTED_VALUE"""),30) -> 30 | J41: =IF(ISERROR(MATCH(G41, $B$8:$B$12, 0)), -1*I41,I41) -> -30 | K41: =DATE(2025, Cashflow!$D$2, $H41) -> 45946
A42: FALSE | B42: Avail Portal | C42: 16 | D42: 18 | F42: =NOT(ISBLANK(C42)) -> TRUE | G42: =IFERROR(__xludf.DUMMYFUNCTION("""COMPUTED_VALUE"""),"Phone (Brittany)") -> Phone (Brittany) | H42: =IFERROR(__xludf.DUMMYFUNCTION("""COMPUTED_VALUE"""),16) -> 16 | I42: =IFERROR(__xludf.DUMMYFUNCTION("""COMPUTED_VALUE"""),50) -> 50 | J42: =IF(ISERROR(MATCH(G42, $B$8:$B$12, 0)), -1*I42,I42) -> -50 | K42: =DATE(2025, Cashflow!$D$2, $H42) -> 45946
...

Sheet 202509
B2: Season | C2: Summer
B4: =SUMIFS(D17:D91, C17:C91, "<=14") -> 1812.24 | C4: Expenses: 1st to 15th
B5: =SUMIFS(D17:D91, C17:C91, ">=15") -> 2369.98 | C5: Expenses: 15th to 30th
B7: Description | C7: Expected Due Date | D7: Amount
A8: =IFERROR(NOT(ISBLANK(C8)), FALSE) -> TRUE | B8: CVS Income | C8: 15 | D8: 3250.73
A9: =IFERROR(NOT(ISBLANK(C9)), FALSE) -> TRUE | B9: CVS Income | C9: 30 | D9: 3250.73
A10: =IFERROR(NOT(ISBLANK(C10)), FALSE) -> FALSE | B10: Apt 2 Rent
A11: =IFERROR(NOT(ISBLANK(C11)), FALSE) -> FALSE | B11: Apt 3 Rent
A12: =IFERROR(NOT(ISBLANK(C12)), FALSE) -> FALSE | B12: Uber Income
A13: =IFERROR(NOT(ISBLANK(C13)), FALSE) -> FALSE
A14: =IFERROR(NOT(ISBLANK(C14)), FALSE) -> FALSE | B14: Total Income | D14: =SUM(D8:D12) -> 6501.46
A15: =IFERROR(NOT(ISBLANK(C15)), FALSE) -> FALSE
A16: =IFERROR(NOT(ISBLANK(C16)), FALSE) -> FALSE | B16: Credit Cards
A17: =IFERROR(NOT(ISBLANK(C17)), FALSE) -> TRUE | B17: BOA Customized Rewards | C17: 9
B18: BOA Unlimited Rewards | C18: 4
B19: CHASE Freedom | C19: 15
B20: CHASE Brittany | C20: 17
B21: CITI Diamond Preferred | C21: 15 | D21: 120
A22: =IFERROR(NOT(ISBLANK(C22)), FALSE) -> TRUE | B22: CITIZENS Clear Value | C22: 13 | D22: 64
A23: =IFERROR(NOT(ISBLANK(C23)), FALSE) -> FALSE
A24: =IFERROR(NOT(ISBLANK(C24)), FALSE) -> FALSE | B24: Loan Payments
A25: =IFERROR(NOT(ISBLANK(C25)), FALSE) -> TRUE | B25: CITIZENS HELOC | C25: 1 | D25: 407
B26: UPSTART Debt Consolidation | C26: 15 | D26: 181.13
A27: =IFERROR(NOT(ISBLANK(C27)), FALSE) -> TRUE | B27: LIGHTSTREAM Renovation | C27: 15
B28: AFFIRM Photography | C28: 21 | D28: 235.17
B29: AQUA FINANCE Roofing Replacement | D29: 268.44
A30: =IFERROR(NOT(ISBLANK(C30)), FALSE) -> TRUE | B30: TD Auto Loan | C30: 17 | D30: 595 | F30: ~$3000 Underwater on loan (ie, need to pay this as a downpayment)
A31: =IFERROR(NOT(ISBLANK(C31)), FALSE) -> FALSE | B31: NELNET Student Loans
A32: =IFERROR(NOT(ISBLANK(C32)), FALSE) -> FALSE
A33: =IFERROR(NOT(ISBLANK(C33)), FALSE) -> FALSE | B33: Propery Expenses
